2023-05-24 22:06:09,379 ERROR: Exception on /search [GET] [in /Users/kyle/.pyenv/versions/microblog/lib/python3.10/site-packages/flask/app.py:1744]
Traceback (most recent call last):
  File "/Users/kyle/.pyenv/versions/microblog/lib/python3.10/site-packages/flask/app.py", line 2528, in wsgi_app
    response = self.full_dispatch_request()
  File "/Users/kyle/.pyenv/versions/microblog/lib/python3.10/site-packages/flask/app.py", line 1825, in full_dispatch_request
    rv = self.handle_user_exception(e)
  File "/Users/kyle/.pyenv/versions/microblog/lib/python3.10/site-packages/flask/app.py", line 1823, in full_dispatch_request
    rv = self.dispatch_request()
  File "/Users/kyle/.pyenv/versions/microblog/lib/python3.10/site-packages/flask/app.py", line 1799, in dispatch_request
    return self.ensure_sync(self.view_functions[rule.endpoint])(**view_args)
  File "/Users/kyle/.pyenv/versions/microblog/lib/python3.10/site-packages/flask_login/utils.py", line 290, in decorated_view
    return current_app.ensure_sync(func)(*args, **kwargs)
  File "/Users/kyle/projects/tester/app/main/routes.py", line 155, in search
    posts, total = Post.search(g.search_form.q.data, page,
  File "/Users/kyle/projects/tester/app/models.py", line 14, in search
    ids, total = query_index(cls.__tablename__, expression, page, per_page)
  File "/Users/kyle/projects/tester/app/search.py", line 19, in query_index
    search = current_app.elasticsearch.search(
  File "/Users/kyle/.pyenv/versions/microblog/lib/python3.10/site-packages/elasticsearch/_sync/client/utils.py", line 414, in wrapped
    return api(*args, **kwargs)
  File "/Users/kyle/.pyenv/versions/microblog/lib/python3.10/site-packages/elasticsearch/_sync/client/__init__.py", line 3857, in search
    return self.perform_request(  # type: ignore[return-value]
  File "/Users/kyle/.pyenv/versions/microblog/lib/python3.10/site-packages/elasticsearch/_sync/client/_base.py", line 285, in perform_request
    meta, resp_body = self.transport.perform_request(
  File "/Users/kyle/.pyenv/versions/microblog/lib/python3.10/site-packages/elastic_transport/_transport.py", line 329, in perform_request
    meta, raw_data = node.perform_request(
  File "/Users/kyle/.pyenv/versions/microblog/lib/python3.10/site-packages/elastic_transport/_node/_http_urllib3.py", line 199, in perform_request
    raise err from None
elastic_transport.ConnectionError: Connection error caused by: ConnectionError(Connection error caused by: NewConnectionError(<urllib3.connection.HTTPConnection object at 0x103b34100>: Failed to establish a new connection: [Errno 61] Connection refused))
2023-05-28 20:32:08,670 INFO: Microblog startup [in /Users/kyle/projects/tester/app/__init__.py:78]
2023-05-28 20:33:02,515 ERROR: Exception on /search [GET] [in /Users/kyle/.pyenv/versions/microblog/lib/python3.10/site-packages/flask/app.py:1744]
Traceback (most recent call last):
  File "/Users/kyle/.pyenv/versions/microblog/lib/python3.10/site-packages/flask/app.py", line 2528, in wsgi_app
    response = self.full_dispatch_request()
  File "/Users/kyle/.pyenv/versions/microblog/lib/python3.10/site-packages/flask/app.py", line 1825, in full_dispatch_request
    rv = self.handle_user_exception(e)
  File "/Users/kyle/.pyenv/versions/microblog/lib/python3.10/site-packages/flask/app.py", line 1823, in full_dispatch_request
    rv = self.dispatch_request()
  File "/Users/kyle/.pyenv/versions/microblog/lib/python3.10/site-packages/flask/app.py", line 1799, in dispatch_request
    return self.ensure_sync(self.view_functions[rule.endpoint])(**view_args)
  File "/Users/kyle/.pyenv/versions/microblog/lib/python3.10/site-packages/flask_login/utils.py", line 290, in decorated_view
    return current_app.ensure_sync(func)(*args, **kwargs)
  File "/Users/kyle/projects/tester/app/main/routes.py", line 155, in search
    posts, total = Post.search(g.search_form.q.data, page,
  File "/Users/kyle/projects/tester/app/models.py", line 14, in search
    ids, total = query_index(cls.__tablename__, expression, page, per_page)
  File "/Users/kyle/projects/tester/app/search.py", line 19, in query_index
    search = current_app.elasticsearch.search(
  File "/Users/kyle/.pyenv/versions/microblog/lib/python3.10/site-packages/elasticsearch/_sync/client/utils.py", line 414, in wrapped
    return api(*args, **kwargs)
  File "/Users/kyle/.pyenv/versions/microblog/lib/python3.10/site-packages/elasticsearch/_sync/client/__init__.py", line 3857, in search
    return self.perform_request(  # type: ignore[return-value]
  File "/Users/kyle/.pyenv/versions/microblog/lib/python3.10/site-packages/elasticsearch/_sync/client/_base.py", line 285, in perform_request
    meta, resp_body = self.transport.perform_request(
  File "/Users/kyle/.pyenv/versions/microblog/lib/python3.10/site-packages/elastic_transport/_transport.py", line 329, in perform_request
    meta, raw_data = node.perform_request(
  File "/Users/kyle/.pyenv/versions/microblog/lib/python3.10/site-packages/elastic_transport/_node/_http_urllib3.py", line 199, in perform_request
    raise err from None
elastic_transport.ConnectionError: Connection error caused by: ConnectionError(Connection error caused by: NewConnectionError(<urllib3.connection.HTTPConnection object at 0x108165300>: Failed to establish a new connection: [Errno 61] Connection refused))
2023-05-28 20:33:13,955 ERROR: Exception on /search [GET] [in /Users/kyle/.pyenv/versions/microblog/lib/python3.10/site-packages/flask/app.py:1744]
Traceback (most recent call last):
  File "/Users/kyle/.pyenv/versions/microblog/lib/python3.10/site-packages/flask/app.py", line 2528, in wsgi_app
    response = self.full_dispatch_request()
  File "/Users/kyle/.pyenv/versions/microblog/lib/python3.10/site-packages/flask/app.py", line 1825, in full_dispatch_request
    rv = self.handle_user_exception(e)
  File "/Users/kyle/.pyenv/versions/microblog/lib/python3.10/site-packages/flask/app.py", line 1823, in full_dispatch_request
    rv = self.dispatch_request()
  File "/Users/kyle/.pyenv/versions/microblog/lib/python3.10/site-packages/flask/app.py", line 1799, in dispatch_request
    return self.ensure_sync(self.view_functions[rule.endpoint])(**view_args)
  File "/Users/kyle/.pyenv/versions/microblog/lib/python3.10/site-packages/flask_login/utils.py", line 290, in decorated_view
    return current_app.ensure_sync(func)(*args, **kwargs)
  File "/Users/kyle/projects/tester/app/main/routes.py", line 155, in search
    posts, total = Post.search(g.search_form.q.data, page,
  File "/Users/kyle/projects/tester/app/models.py", line 14, in search
    ids, total = query_index(cls.__tablename__, expression, page, per_page)
  File "/Users/kyle/projects/tester/app/search.py", line 19, in query_index
    search = current_app.elasticsearch.search(
  File "/Users/kyle/.pyenv/versions/microblog/lib/python3.10/site-packages/elasticsearch/_sync/client/utils.py", line 414, in wrapped
    return api(*args, **kwargs)
  File "/Users/kyle/.pyenv/versions/microblog/lib/python3.10/site-packages/elasticsearch/_sync/client/__init__.py", line 3857, in search
    return self.perform_request(  # type: ignore[return-value]
  File "/Users/kyle/.pyenv/versions/microblog/lib/python3.10/site-packages/elasticsearch/_sync/client/_base.py", line 285, in perform_request
    meta, resp_body = self.transport.perform_request(
  File "/Users/kyle/.pyenv/versions/microblog/lib/python3.10/site-packages/elastic_transport/_transport.py", line 329, in perform_request
    meta, raw_data = node.perform_request(
  File "/Users/kyle/.pyenv/versions/microblog/lib/python3.10/site-packages/elastic_transport/_node/_http_urllib3.py", line 199, in perform_request
    raise err from None
elastic_transport.ConnectionError: Connection error caused by: ConnectionError(Connection error caused by: NewConnectionError(<urllib3.connection.HTTPConnection object at 0x107fe34c0>: Failed to establish a new connection: [Errno 61] Connection refused))
2023-06-03 12:10:30,572 INFO: Microblog startup [in /Users/kyle/projects/tester/app/__init__.py:78]
2023-06-03 12:25:35,015 INFO: Microblog startup [in /Users/kyle/projects/tester/app/__init__.py:78]
2023-06-03 12:41:10,091 INFO: Microblog startup [in /Users/kyle/projects/tester/app/__init__.py:78]
