2023-04-07 19:23:21,867 ERROR: Exception on /reset_password_request [GET] [in /Users/kyle/projects/tester/sirtestalot/lib/python3.11/site-packages/flask/app.py:1744]
Traceback (most recent call last):
  File "/Users/kyle/projects/tester/sirtestalot/lib/python3.11/site-packages/flask/app.py", line 2528, in wsgi_app
    response = self.full_dispatch_request()
               ^^^^^^^^^^^^^^^^^^^^^^^^^^^^
  File "/Users/kyle/projects/tester/sirtestalot/lib/python3.11/site-packages/flask/app.py", line 1825, in full_dispatch_request
    rv = self.handle_user_exception(e)
         ^^^^^^^^^^^^^^^^^^^^^^^^^^^^^
  File "/Users/kyle/projects/tester/sirtestalot/lib/python3.11/site-packages/flask/app.py", line 1823, in full_dispatch_request
    rv = self.dispatch_request()
         ^^^^^^^^^^^^^^^^^^^^^^^
  File "/Users/kyle/projects/tester/sirtestalot/lib/python3.11/site-packages/flask/app.py", line 1799, in dispatch_request
    return self.ensure_sync(self.view_functions[rule.endpoint])(**view_args)
           ^^^^^^^^^^^^^^^^^^^^^^^^^^^^^^^^^^^^^^^^^^^^^^^^^^^^^^^^^^^^^^^^^
  File "/Users/kyle/projects/tester/app/routes.py", line 158, in reset_password_request
    form = ResetPasswordRequestForm()
           ^^^^^^^^^^^^^^^^^^^^^^^^^^
  File "/Users/kyle/projects/tester/sirtestalot/lib/python3.11/site-packages/wtforms/form.py", line 208, in __call__
    return type.__call__(cls, *args, **kwargs)
           ^^^^^^^^^^^^^^^^^^^^^^^^^^^^^^^^^^^
  File "/Users/kyle/projects/tester/sirtestalot/lib/python3.11/site-packages/flask_wtf/form.py", line 73, in __init__
    super().__init__(formdata=formdata, **kwargs)
  File "/Users/kyle/projects/tester/sirtestalot/lib/python3.11/site-packages/wtforms/form.py", line 280, in __init__
    super().__init__(self._unbound_fields, meta=meta_obj, prefix=prefix)
  File "/Users/kyle/projects/tester/sirtestalot/lib/python3.11/site-packages/wtforms/form.py", line 48, in __init__
    field = meta.bind_field(self, unbound_field, options)
            ^^^^^^^^^^^^^^^^^^^^^^^^^^^^^^^^^^^^^^^^^^^^^
  File "/Users/kyle/projects/tester/sirtestalot/lib/python3.11/site-packages/wtforms/meta.py", line 28, in bind_field
    return unbound_field.bind(form=form, **options)
           ^^^^^^^^^^^^^^^^^^^^^^^^^^^^^^^^^^^^^^^^
  File "/Users/kyle/projects/tester/sirtestalot/lib/python3.11/site-packages/wtforms/fields/core.py", line 395, in bind
    return self.field_class(*self.args, **kw)
           ^^^^^^^^^^^^^^^^^^^^^^^^^^^^^^^^^^
TypeError: Field.__init__() got an unexpected keyword argument 'calidators'
2023-04-07 19:29:30,822 INFO: Microblog startup [in /Users/kyle/projects/tester/app/__init__.py:48]
2023-04-07 19:29:39,531 ERROR: Exception on /reset_password_request [GET] [in /Users/kyle/projects/tester/sirtestalot/lib/python3.11/site-packages/flask/app.py:1744]
Traceback (most recent call last):
  File "/Users/kyle/projects/tester/sirtestalot/lib/python3.11/site-packages/flask/app.py", line 2528, in wsgi_app
    response = self.full_dispatch_request()
               ^^^^^^^^^^^^^^^^^^^^^^^^^^^^
  File "/Users/kyle/projects/tester/sirtestalot/lib/python3.11/site-packages/flask/app.py", line 1825, in full_dispatch_request
    rv = self.handle_user_exception(e)
         ^^^^^^^^^^^^^^^^^^^^^^^^^^^^^
  File "/Users/kyle/projects/tester/sirtestalot/lib/python3.11/site-packages/flask/app.py", line 1823, in full_dispatch_request
    rv = self.dispatch_request()
         ^^^^^^^^^^^^^^^^^^^^^^^
  File "/Users/kyle/projects/tester/sirtestalot/lib/python3.11/site-packages/flask/app.py", line 1799, in dispatch_request
    return self.ensure_sync(self.view_functions[rule.endpoint])(**view_args)
           ^^^^^^^^^^^^^^^^^^^^^^^^^^^^^^^^^^^^^^^^^^^^^^^^^^^^^^^^^^^^^^^^^
  File "/Users/kyle/projects/tester/app/routes.py", line 158, in reset_password_request
    form = ResetPasswordRequestForm()
           ^^^^^^^^^^^^^^^^^^^^^^^^^^
  File "/Users/kyle/projects/tester/sirtestalot/lib/python3.11/site-packages/wtforms/form.py", line 208, in __call__
    return type.__call__(cls, *args, **kwargs)
           ^^^^^^^^^^^^^^^^^^^^^^^^^^^^^^^^^^^
  File "/Users/kyle/projects/tester/sirtestalot/lib/python3.11/site-packages/flask_wtf/form.py", line 73, in __init__
    super().__init__(formdata=formdata, **kwargs)
  File "/Users/kyle/projects/tester/sirtestalot/lib/python3.11/site-packages/wtforms/form.py", line 280, in __init__
    super().__init__(self._unbound_fields, meta=meta_obj, prefix=prefix)
  File "/Users/kyle/projects/tester/sirtestalot/lib/python3.11/site-packages/wtforms/form.py", line 48, in __init__
    field = meta.bind_field(self, unbound_field, options)
            ^^^^^^^^^^^^^^^^^^^^^^^^^^^^^^^^^^^^^^^^^^^^^
  File "/Users/kyle/projects/tester/sirtestalot/lib/python3.11/site-packages/wtforms/meta.py", line 28, in bind_field
    return unbound_field.bind(form=form, **options)
           ^^^^^^^^^^^^^^^^^^^^^^^^^^^^^^^^^^^^^^^^
  File "/Users/kyle/projects/tester/sirtestalot/lib/python3.11/site-packages/wtforms/fields/core.py", line 395, in bind
    return self.field_class(*self.args, **kw)
           ^^^^^^^^^^^^^^^^^^^^^^^^^^^^^^^^^^
TypeError: Field.__init__() got an unexpected keyword argument 'calidators'
2023-04-07 19:32:45,668 INFO: Microblog startup [in /Users/kyle/projects/tester/app/__init__.py:48]
2023-04-10 11:10:55,701 INFO: Microblog startup [in /Users/kyle/projects/tester/app/__init__.py:50]
2023-04-10 11:16:46,222 INFO: Microblog startup [in /Users/kyle/projects/tester/app/__init__.py:50]
2023-04-10 11:20:46,351 INFO: Microblog startup [in /Users/kyle/projects/tester/app/__init__.py:50]
2023-04-10 11:41:10,423 INFO: Microblog startup [in /Users/kyle/projects/tester/app/__init__.py:51]
2023-04-10 12:13:56,558 INFO: Microblog startup [in /Users/kyle/projects/tester/app/__init__.py:51]
2023-04-10 12:14:03,277 ERROR: Exception on /index [GET] [in /Users/kyle/projects/tester/sirtestalot/lib/python3.11/site-packages/flask/app.py:1744]
Traceback (most recent call last):
  File "/Users/kyle/projects/tester/sirtestalot/lib/python3.11/site-packages/flask/app.py", line 2528, in wsgi_app
    response = self.full_dispatch_request()
               ^^^^^^^^^^^^^^^^^^^^^^^^^^^^
  File "/Users/kyle/projects/tester/sirtestalot/lib/python3.11/site-packages/flask/app.py", line 1825, in full_dispatch_request
    rv = self.handle_user_exception(e)
         ^^^^^^^^^^^^^^^^^^^^^^^^^^^^^
  File "/Users/kyle/projects/tester/sirtestalot/lib/python3.11/site-packages/flask/app.py", line 1823, in full_dispatch_request
    rv = self.dispatch_request()
         ^^^^^^^^^^^^^^^^^^^^^^^
  File "/Users/kyle/projects/tester/sirtestalot/lib/python3.11/site-packages/flask/app.py", line 1799, in dispatch_request
    return self.ensure_sync(self.view_functions[rule.endpoint])(**view_args)
           ^^^^^^^^^^^^^^^^^^^^^^^^^^^^^^^^^^^^^^^^^^^^^^^^^^^^^^^^^^^^^^^^^
  File "/Users/kyle/projects/tester/sirtestalot/lib/python3.11/site-packages/flask_login/utils.py", line 290, in decorated_view
    return current_app.ensure_sync(func)(*args, **kwargs)
           ^^^^^^^^^^^^^^^^^^^^^^^^^^^^^^^^^^^^^^^^^^^^^^
  File "/Users/kyle/projects/tester/app/routes.py", line 36, in index
    return render_template('index.html', title='Home', form=form, posts=posts.items, next_url=next_url, prev_url=prev_url)
           ^^^^^^^^^^^^^^^^^^^^^^^^^^^^^^^^^^^^^^^^^^^^^^^^^^^^^^^^^^^^^^^^^^^^^^^^^^^^^^^^^^^^^^^^^^^^^^^^^^^^^^^^^^^^^^^
  File "/Users/kyle/projects/tester/sirtestalot/lib/python3.11/site-packages/flask/templating.py", line 147, in render_template
    return _render(app, template, context)
           ^^^^^^^^^^^^^^^^^^^^^^^^^^^^^^^
  File "/Users/kyle/projects/tester/sirtestalot/lib/python3.11/site-packages/flask/templating.py", line 130, in _render
    rv = template.render(context)
         ^^^^^^^^^^^^^^^^^^^^^^^^
  File "/Users/kyle/projects/tester/sirtestalot/lib/python3.11/site-packages/jinja2/environment.py", line 1301, in render
    self.environment.handle_exception()
  File "/Users/kyle/projects/tester/sirtestalot/lib/python3.11/site-packages/jinja2/environment.py", line 936, in handle_exception
    raise rewrite_traceback_stack(source=source)
  File "/Users/kyle/projects/tester/app/templates/index.html", line 1, in top-level template code
    {% extends "base.html" %}
  File "/Users/kyle/projects/tester/sirtestalot/lib/python3.11/site-packages/jinja2/environment.py", line 936, in handle_exception
    raise rewrite_traceback_stack(source=source)
  File "/Users/kyle/projects/tester/app/templates/base.html", line 54, in template
    {% endblock %}
jinja2.exceptions.TemplateSyntaxError: Unexpected end of template. Jinja was looking for the following tags: 'endblock'. The innermost block that needs to be closed is 'block'.
2023-04-10 12:15:44,765 INFO: Microblog startup [in /Users/kyle/projects/tester/app/__init__.py:51]
