2023-04-03 13:49:30,613 ERROR: Exception on /explore [GET] [in /Users/kyle/projects/tester/sirtestalot/lib/python3.11/site-packages/flask/app.py:1744]
Traceback (most recent call last):
  File "/Users/kyle/projects/tester/sirtestalot/lib/python3.11/site-packages/flask/app.py", line 2528, in wsgi_app
    response = self.full_dispatch_request()
               ^^^^^^^^^^^^^^^^^^^^^^^^^^^^
  File "/Users/kyle/projects/tester/sirtestalot/lib/python3.11/site-packages/flask/app.py", line 1825, in full_dispatch_request
    rv = self.handle_user_exception(e)
         ^^^^^^^^^^^^^^^^^^^^^^^^^^^^^
  File "/Users/kyle/projects/tester/sirtestalot/lib/python3.11/site-packages/flask/app.py", line 1823, in full_dispatch_request
    rv = self.dispatch_request()
         ^^^^^^^^^^^^^^^^^^^^^^^
  File "/Users/kyle/projects/tester/sirtestalot/lib/python3.11/site-packages/flask/app.py", line 1799, in dispatch_request
    return self.ensure_sync(self.view_functions[rule.endpoint])(**view_args)
           ^^^^^^^^^^^^^^^^^^^^^^^^^^^^^^^^^^^^^^^^^^^^^^^^^^^^^^^^^^^^^^^^^
  File "/Users/kyle/projects/tester/sirtestalot/lib/python3.11/site-packages/flask_login/utils.py", line 290, in decorated_view
    return current_app.ensure_sync(func)(*args, **kwargs)
           ^^^^^^^^^^^^^^^^^^^^^^^^^^^^^^^^^^^^^^^^^^^^^^
  File "/Users/kyle/projects/tester/app/routes.py", line 147, in explore
    return render_template("index.html", title='Explore', posts=posts.items, next_url=next_url, prev_url=prev_url)
           ^^^^^^^^^^^^^^^^^^^^^^^^^^^^^^^^^^^^^^^^^^^^^^^^^^^^^^^^^^^^^^^^^^^^^^^^^^^^^^^^^^^^^^^^^^^^^^^^^^^^^^^
  File "/Users/kyle/projects/tester/sirtestalot/lib/python3.11/site-packages/flask/templating.py", line 146, in render_template
    template = app.jinja_env.get_or_select_template(template_name_or_list)
               ^^^^^^^^^^^^^^^^^^^^^^^^^^^^^^^^^^^^^^^^^^^^^^^^^^^^^^^^^^^
  File "/Users/kyle/projects/tester/sirtestalot/lib/python3.11/site-packages/jinja2/environment.py", line 1081, in get_or_select_template
    return self.get_template(template_name_or_list, parent, globals)
           ^^^^^^^^^^^^^^^^^^^^^^^^^^^^^^^^^^^^^^^^^^^^^^^^^^^^^^^^^
  File "/Users/kyle/projects/tester/sirtestalot/lib/python3.11/site-packages/jinja2/environment.py", line 1010, in get_template
    return self._load_template(name, globals)
           ^^^^^^^^^^^^^^^^^^^^^^^^^^^^^^^^^^
  File "/Users/kyle/projects/tester/sirtestalot/lib/python3.11/site-packages/jinja2/environment.py", line 969, in _load_template
    template = self.loader.load(self, name, self.make_globals(globals))
               ^^^^^^^^^^^^^^^^^^^^^^^^^^^^^^^^^^^^^^^^^^^^^^^^^^^^^^^^
  File "/Users/kyle/projects/tester/sirtestalot/lib/python3.11/site-packages/jinja2/loaders.py", line 138, in load
    code = environment.compile(source, name, filename)
           ^^^^^^^^^^^^^^^^^^^^^^^^^^^^^^^^^^^^^^^^^^^
  File "/Users/kyle/projects/tester/sirtestalot/lib/python3.11/site-packages/jinja2/environment.py", line 768, in compile
    self.handle_exception(source=source_hint)
  File "/Users/kyle/projects/tester/sirtestalot/lib/python3.11/site-packages/jinja2/environment.py", line 936, in handle_exception
    raise rewrite_traceback_stack(source=source)
  File "/Users/kyle/projects/tester/app/templates/index.html", line 25, in template
    {% endif %}
jinja2.exceptions.TemplateSyntaxError: Encountered unknown tag 'endif'. Jinja was looking for the following tags: 'endblock'. The innermost block that needs to be closed is 'block'.
2023-04-03 13:51:07,184 INFO: Microblog startup [in /Users/kyle/projects/tester/app/__init__.py:46]
2023-04-03 14:00:44,091 INFO: Microblog startup [in /Users/kyle/projects/tester/app/__init__.py:46]
2023-04-07 12:29:38,206 INFO: Microblog startup [in /Users/kyle/projects/tester/app/__init__.py:48]
2023-04-07 18:15:10,878 INFO: Microblog startup [in /Users/kyle/projects/tester/app/__init__.py:48]
2023-04-07 19:07:48,630 INFO: Microblog startup [in /Users/kyle/projects/tester/app/__init__.py:48]
2023-04-07 19:08:05,371 ERROR: Exception on /reset_password_request [GET] [in /Users/kyle/projects/tester/sirtestalot/lib/python3.11/site-packages/flask/app.py:1744]
Traceback (most recent call last):
  File "/Users/kyle/projects/tester/sirtestalot/lib/python3.11/site-packages/flask/app.py", line 2528, in wsgi_app
    response = self.full_dispatch_request()
               ^^^^^^^^^^^^^^^^^^^^^^^^^^^^
  File "/Users/kyle/projects/tester/sirtestalot/lib/python3.11/site-packages/flask/app.py", line 1825, in full_dispatch_request
    rv = self.handle_user_exception(e)
         ^^^^^^^^^^^^^^^^^^^^^^^^^^^^^
  File "/Users/kyle/projects/tester/sirtestalot/lib/python3.11/site-packages/flask/app.py", line 1823, in full_dispatch_request
    rv = self.dispatch_request()
         ^^^^^^^^^^^^^^^^^^^^^^^
  File "/Users/kyle/projects/tester/sirtestalot/lib/python3.11/site-packages/flask/app.py", line 1799, in dispatch_request
    return self.ensure_sync(self.view_functions[rule.endpoint])(**view_args)
           ^^^^^^^^^^^^^^^^^^^^^^^^^^^^^^^^^^^^^^^^^^^^^^^^^^^^^^^^^^^^^^^^^
  File "/Users/kyle/projects/tester/app/routes.py", line 157, in reset_password_request
    form = ResetPasswordRequestForm()
           ^^^^^^^^^^^^^^^^^^^^^^^^^^
  File "/Users/kyle/projects/tester/sirtestalot/lib/python3.11/site-packages/wtforms/form.py", line 208, in __call__
    return type.__call__(cls, *args, **kwargs)
           ^^^^^^^^^^^^^^^^^^^^^^^^^^^^^^^^^^^
  File "/Users/kyle/projects/tester/sirtestalot/lib/python3.11/site-packages/flask_wtf/form.py", line 73, in __init__
    super().__init__(formdata=formdata, **kwargs)
  File "/Users/kyle/projects/tester/sirtestalot/lib/python3.11/site-packages/wtforms/form.py", line 280, in __init__
    super().__init__(self._unbound_fields, meta=meta_obj, prefix=prefix)
  File "/Users/kyle/projects/tester/sirtestalot/lib/python3.11/site-packages/wtforms/form.py", line 48, in __init__
    field = meta.bind_field(self, unbound_field, options)
            ^^^^^^^^^^^^^^^^^^^^^^^^^^^^^^^^^^^^^^^^^^^^^
  File "/Users/kyle/projects/tester/sirtestalot/lib/python3.11/site-packages/wtforms/meta.py", line 28, in bind_field
    return unbound_field.bind(form=form, **options)
           ^^^^^^^^^^^^^^^^^^^^^^^^^^^^^^^^^^^^^^^^
  File "/Users/kyle/projects/tester/sirtestalot/lib/python3.11/site-packages/wtforms/fields/core.py", line 395, in bind
    return self.field_class(*self.args, **kw)
           ^^^^^^^^^^^^^^^^^^^^^^^^^^^^^^^^^^
TypeError: Field.__init__() got an unexpected keyword argument 'calidators'
2023-04-07 19:11:23,000 ERROR: Exception on /reset_password_request [GET] [in /Users/kyle/projects/tester/sirtestalot/lib/python3.11/site-packages/flask/app.py:1744]
Traceback (most recent call last):
  File "/Users/kyle/projects/tester/sirtestalot/lib/python3.11/site-packages/flask/app.py", line 2528, in wsgi_app
    response = self.full_dispatch_request()
               ^^^^^^^^^^^^^^^^^^^^^^^^^^^^
  File "/Users/kyle/projects/tester/sirtestalot/lib/python3.11/site-packages/flask/app.py", line 1825, in full_dispatch_request
    rv = self.handle_user_exception(e)
         ^^^^^^^^^^^^^^^^^^^^^^^^^^^^^
  File "/Users/kyle/projects/tester/sirtestalot/lib/python3.11/site-packages/flask/app.py", line 1823, in full_dispatch_request
    rv = self.dispatch_request()
         ^^^^^^^^^^^^^^^^^^^^^^^
  File "/Users/kyle/projects/tester/sirtestalot/lib/python3.11/site-packages/flask/app.py", line 1799, in dispatch_request
    return self.ensure_sync(self.view_functions[rule.endpoint])(**view_args)
           ^^^^^^^^^^^^^^^^^^^^^^^^^^^^^^^^^^^^^^^^^^^^^^^^^^^^^^^^^^^^^^^^^
  File "/Users/kyle/projects/tester/app/routes.py", line 157, in reset_password_request
    form = ResetPasswordRequestForm()
           ^^^^^^^^^^^^^^^^^^^^^^^^^^
  File "/Users/kyle/projects/tester/sirtestalot/lib/python3.11/site-packages/wtforms/form.py", line 208, in __call__
    return type.__call__(cls, *args, **kwargs)
           ^^^^^^^^^^^^^^^^^^^^^^^^^^^^^^^^^^^
  File "/Users/kyle/projects/tester/sirtestalot/lib/python3.11/site-packages/flask_wtf/form.py", line 73, in __init__
    super().__init__(formdata=formdata, **kwargs)
  File "/Users/kyle/projects/tester/sirtestalot/lib/python3.11/site-packages/wtforms/form.py", line 280, in __init__
    super().__init__(self._unbound_fields, meta=meta_obj, prefix=prefix)
  File "/Users/kyle/projects/tester/sirtestalot/lib/python3.11/site-packages/wtforms/form.py", line 48, in __init__
    field = meta.bind_field(self, unbound_field, options)
            ^^^^^^^^^^^^^^^^^^^^^^^^^^^^^^^^^^^^^^^^^^^^^
  File "/Users/kyle/projects/tester/sirtestalot/lib/python3.11/site-packages/wtforms/meta.py", line 28, in bind_field
    return unbound_field.bind(form=form, **options)
           ^^^^^^^^^^^^^^^^^^^^^^^^^^^^^^^^^^^^^^^^
  File "/Users/kyle/projects/tester/sirtestalot/lib/python3.11/site-packages/wtforms/fields/core.py", line 395, in bind
    return self.field_class(*self.args, **kw)
           ^^^^^^^^^^^^^^^^^^^^^^^^^^^^^^^^^^
TypeError: Field.__init__() got an unexpected keyword argument 'calidators'
2023-04-07 19:14:07,475 INFO: Microblog startup [in /Users/kyle/projects/tester/app/__init__.py:48]
